<?xml version="1.0"?>
<robot xmlns:xacro="http://www.ros.org/wiki/xacro" name="my_bot">

    <!-- base_footprint -->
    <link name="base_footprint"/>

    <!-- base_link -->
  <link
    name="base_link">
    <inertial>
      <origin
        xyz="-1.1536E-16 -8.6736E-17 0.13512"
        rpy="0 0 0" />
      <mass
        value="201.67" />
      <inertia
        ixx="9.5313"
        ixy="-9.2157E-16"
        ixz="-5.6579E-16"
        iyy="22.658"
        iyz="-4.198E-17"
        izz="30.077" />
    </inertial>
    <visual>
      <origin
        xyz="0 0 0"
        rpy="0 0 0" />
      <geometry>
            <mesh filename="file://$(find my_bot)/meshes/base_link.STL"/>
      </geometry>
      <material
        name="">
        <color
          rgba="0.79216 0.81961 0.93333 1" />
      </material>
    </visual>
    <collision>
      <origin
        xyz="0 0 0"
        rpy="0 0 0" />
      <geometry>
            <mesh filename="file://$(find my_bot)/meshes/base_link.STL"/>
      </geometry>
    </collision>
  </link>

    <!-- base_footprint -> base_link joint -->
    <joint name="base_footprint_joint" type="fixed">
        <origin xyz="0 0 0" rpy="0 0 0"/>
        <parent link="base_footprint"/>
        <child link="base_link"/>
    </joint>

   <link
    name="left_wheel">
    <inertial>
      <origin
        xyz="6.0715E-18 -0.02 0"
        rpy="0 0 0" />
      <mass
        value="0.80425" />
      <inertia
        ixx="0.001394"
        ixy="6.1901E-35"
        ixz="7.1778E-51"
        iyy="0.0025736"
        iyz="2.4867E-36"
        izz="0.001394" />
    </inertial>
    <visual>
      <origin
        xyz="0 0 0"
        rpy="0 0 0" />
      <geometry>
        <mesh filename="file://$(find my_bot)/meshes/left_wheel.STL"/>
      </geometry>
      <material
        name="">
        <color
          rgba="0.79216 0.81961 0.93333 1" />
      </material>
    </visual>
    <collision>
      <origin
        xyz="0 0 0"
        rpy="0 0 0" />
      <geometry>
        <mesh filename="file://$(find my_bot)/meshes/left_wheel.STL"/>

      </geometry>
    </collision>
  </link>
  <joint
    name="leftwheel"
    type="continuous">
    <origin
      xyz="0 0.406 0.018995"
      rpy="0 0 0" />
    <parent
      link="base_link" />
    <child
      link="left_wheel" />
    <axis
      xyz="0 1 0" />
    <dynamics
      friction="0.1" />
  </joint>


    <link
    name="right_wheel">
    <inertial>
      <origin
        xyz="6.9389E-18 0.02 0"
        rpy="0 0 0" />
      <mass
        value="0.80425" />
      <inertia
        ixx="0.001394"
        ixy="6.1901E-35"
        ixz="7.1778E-51"
        iyy="0.0025736"
        iyz="2.4867E-36"
        izz="0.001394" />
    </inertial>
    <visual>
      <origin
        xyz="0 0 0"
        rpy="0 0 0" />
      <geometry>
        <mesh filename="file://$(find my_bot)/meshes/right_wheel.STL"/>

      </geometry>
      <material
        name="">
        <color
          rgba="0.79216 0.81961 0.93333 1" />
      </material>
    </visual>
    <collision>
      <origin
        xyz="0 0 0"
        rpy="0 0 0" />
      <geometry>
        <mesh filename="file://$(find my_bot)/meshes/right_wheel.STL"/>

      </geometry>
    </collision>
  </link>
  <joint
    name="rightwheel"
    type="continuous">
    <origin
      xyz="0 -0.406 0.018995"
      rpy="0 0 0" />
    <parent
      link="base_link" />
    <child
      link="right_wheel" />
    <axis
      xyz="0 1 0" />
    <dynamics
      friction="0.1" />
  </joint>


    <link
    name="lidar_link">
    <inertial>
      <origin
        xyz="-8.6736E-18 0 -0.02"
        rpy="0 0 0" />
      <mass
        value="0.45239" />
      <inertia
        ixx="0.00046747"
        ixy="0"
        ixz="-1.4694E-36"
        iyy="0.00046747"
        iyz="-1.0491E-36"
        izz="0.0008143" />
    </inertial>
    <visual>
      <origin
        xyz="0 0 0"
        rpy="0 0 0" />
      <geometry>
        <mesh filename="file://$(find my_bot)/meshes/lidar_link.STL"/>

      </geometry>
       <material
        name="">
        <color
          rgba="0.79216 0.81961 0.93333 1" />
      </material>
    </visual>
    <collision>
      <origin
        xyz="0 0 0"
        rpy="0 0 0" />
      <geometry>
        <mesh filename="file://$(find my_bot)/meshes/lidar_link.STL"/>

      </geometry>
    </collision>
  </link>
  <joint
    name="lidar_joint"
    type="fixed">
    <origin
      xyz="0 0 0.29909"
      rpy="0 0 0" />
    <parent
      link="base_link" />
    <child
      link="lidar_link" />
    <axis
      xyz="0 0 1" />
  </joint>


  <joint name="camera_joint" type="fixed">
        <parent link="base_link"/>
        <child link="camera_link"/>
        <origin xyz="0.6 0 0.2" rpy="0 ${pi/2} 0"/>
  </joint>

  <link name="camera_link">
      <visual>
          <geometry>
              <box size="0.010 0.03 0.03"/>
          </geometry>
            <material
            name="">
            <color
              rgba="0.79216 0.81961 0.93333 1" />
          </material>
      </visual>
  </link>


  <joint name="camera_optical_joint" type="fixed">
      <parent link="camera_link"/>
      <child link="camera_link_optical"/>
      <origin xyz="0 0 0" rpy="${-pi/2} 0 ${-pi/2}"/>
  </joint>

  <link name="camera_link_optical"></link>
</robot>